# 10. tananyag

:::tip üìö EBBEN A FEJEZETBEN
- A kiv√©telek megismer√©se
- A hib√°k helyes kezel√©se
- Az alkalmaz√°s √∂sszeoml√°s√°nak megakad√°lyoz√°sa
- A `try` ... `except` ... `else` ... `finally` haszn√°lata
- Saj√°t kiv√©telek k√©sz√≠t√©se
:::

Mindannyian azt szeretn√©nk, hogy ha programjaink mindig t√∂k√©letesen futn√°nak. De n√©ha el≈ëfordulnak olyan helyzetek, amelyek megakad√°lyozz√°k a program fut√°s√°t. A probl√©ma nem a k√≥doddal vagy a programoddal van. √Åltal√°ban a programot haszn√°l√≥ szem√©ly csin√°lt valamit rosszul. A hibakezel√©s l√©nyege, hogy el≈ëre l√°tjuk ezeket a probl√©m√°kat, √©szlelj√ºk a hib√°t, majd t√°j√©koztatjuk a felhaszn√°l√≥kat a probl√©m√°r√≥l, hogy kitudj√°k jav√≠tani azt.

Az itt le√≠rt technik√°k nem a k√≥dodban l√©v≈ë hib√°k jav√≠t√°s√°ra szolg√°lnak. Az ilyen t√≠pus√∫ hib√°kat magadnak kell kijav√≠tanod. Szigor√∫an a program futtat√°si k√∂rnyezet√©ben fell√©p≈ë hib√°kr√≥l besz√©l√ºnk, amelyekre nincs r√°hat√°sa. A hibakezel√©s egyszer≈±en csak egy m√≥dja annak, hogy a Python √°ltal √°ltal√°ban megjelen√≠tett, a legt√∂bb ember sz√°m√°ra √©rtelmetlen, technikai nyelven megfogalmazott hiba√ºzenetet egy olyan √ºzenettel helyettes√≠ts√ºk, amely k√∂z√©rthet≈ëen elmondja, hogy mi a baj, √©s ide√°lis esetben azt is, hogy hogyan jav√≠tsuk ki.

_Ism√©tlem, a felhaszn√°l√≥ azt a k√∂rnyezetet jav√≠tja, amelyben a program fut - nem a k√≥dodat jav√≠tja._

## A kiv√©telek meg√©rt√©se

A Pythonban (√©s minden m√°s programoz√°si nyelvben) a kiv√©tel kifejez√©s olyan hib√°ra utal, amely nem programoz√°si hiba miatt k√∂vetkezik be. Ink√°bb egy olyan hiba, amely megakad√°lyozza a program megfelel≈ë fut√°s√°t. Egy egyszer≈± p√©ld√°val √©lve, legyen a Python alkalmaz√°sunk egy f√°jl megnyit√°sa. Ennek szintaxisa egyszer≈±:

```py
name = open(filename)
```

A `name`-t helyettes√≠ts√ºk egy szabadon v√°lasztott n√©vvel, ugyan√∫gy, mint egy v√°ltoz√≥ nev√©t. A `filename` helyettes√≠ts√ºk a f√°jl nev√©vel. Ha a f√°jl ugyanabban a mapp√°ban van, mint a k√≥d, nem kell megadnod a mappa el√©r√©si √∫tvonal√°t, mert az aktu√°lis mapp√°t haszn√°lja.

A p√©ld√°hoz a __VS Code__ programot haszn√°ljuk, √≠gy l√°that√≥ a mappa tartalma, amelyben dolgozunk. A mappa tartalmaz egy `showfilecontents.py` nev≈± f√°jlt, amely az √°ltalunk √≠rt Python-k√≥dot tartalmazza. A m√°sik f√°jl neve `people.csv`.

__people.csv tartalma:__

```csv
Username,FirstName,LastName,Role,DateJoined
Rambo,Rocco,Moe,0,3/1/2019
Ann,Annie,Angst,0,6/4/2019
Wil,Wilbur,Blomgren,0,2/28/2019
Lupe,Lupe,Gomez,1,4/2/2019
Ina,Ina,Kumar,1,1/15/2019
```


A `showfilecontents` f√°jl k√≥dot tartalmaz. A `people.csv` f√°jl adatokat (az emberekre vonatkoz√≥ inform√°ci√≥kat) tartalmaz. A `people.csv` f√°jl tartalm√°t mutatjuk Excelben (fent), hogy k√∂nnyen olvashat√≥ legyen, √©s sz√∂vegszerkeszt≈ëben (lent), √≠gy n√©z ki a Python √©s m√°s nyelvek sz√°m√°ra. A f√°jl tartalma most nem sokat sz√°m√≠t, amit itt megtanulsz, az b√°rmilyen k√ºls≈ë f√°jlban m≈±k√∂dni fog.

A Python k√≥d mind√∂ssze k√©t sor (a megjegyz√©seket lesz√°m√≠tva), az al√°bbiak szerint:

```py
# Open file that's in this same folder.
thefile = open('people.csv')
# Show the filename.
print(thefile.name)
```

Az els≈ë k√≥dsor megnyitja a `people.csv` nev≈± f√°jlt. A m√°sodik k√≥dsor megjelen√≠ti a f√°jl nev√©t a k√©perny≈ën. Ennek az egyszer≈± `showfilecontents.py` f√°jlnak a futtat√°sa (_a VS Code-ban a nev√©re jobb eg√©rgombbal kattintva, majd a Python f√°jl futtat√°sa a termin√°lban parancsot v√°lasztva_) megjelen√≠ti a `people.csv` f√°jlt a k√©perny≈ën - felt√©ve, hogy a megnyitand√≥ mapp√°ban l√©tezik egy `people.csv` nev≈± f√°jl. Ezut√°n j√∂n a kiv√©telkezel√©s.


![people.csv](/assets/images/python/10/1.jpg)

Tegy√ºk fel, hogy rajtad k√≠v√ºl √°ll√≥ okokb√≥l a `people.csv` f√°jl nincs ott, mert egy szem√©ly vagy egy automatiz√°lt elj√°r√°s elmulasztotta elhelyezni. Vagy esetleg valaki el√≠rta a f√°jlnevet. K√∂nnyen el≈ëfordulhat, hogy v√©letlen√ºl mondjuk __.csv__ helyett __.cvs__-t √≠runk be a f√°jln√©vhez. Az alkalmaz√°s futtat√°sa kiv√©telt (_ami magyarul annyit jelent, hogy "hiba√ºzenetet jelen√≠t meg"_) dob, amit a Terminal ablakban l√°thatunk:

```txt
Traceback (most recent call last):
  File "/Python/1.py", line 2, in <module>
    thefile = open('people.csv')
              ^^^^^^^^^^^^^^^^^^
FileNotFoundError: [Errno 2] No such file or directory: 'people.csv'
```

A `Traceback` egy utal√°s arra, hogy ha t√∂bb kiv√©tel lenne, akkor ezek mind fel lenn√©nek sorolva, √©s a legut√≥bbi lenne az els≈ë. Ebben az esetben csak egy kiv√©tel van. A `File` r√©sz azt mondja meg, hogy hol t√∂rt√©nt a kiv√©tel, a `showfilecontents.py` f√°jl m√°sodik sor√°ban. A k√∂vetkez≈ë r√©sz megmutatja a hib√°t okoz√≥ k√≥dsort:

```py
thefile = open('people.csv')
```

V√©g√ºl pedig maga a kiv√©tel ker√ºl le√≠r√°sra: 

```txt
FileNotFoundError: [Errno 2] No such file or directory: 'people.csv'.
```

Az ilyen t√≠pus√∫ hiba √°ltal√°nos neve `FileNotFoundError`. Sok kiv√©telhez egy sz√°m is tartozik (_ebben a p√©ld√°ban Errno 2_). A sz√°m azonban az oper√°ci√≥s rendszer k√∂rnyezet√©t≈ël f√ºgg≈ëen v√°ltozhat, ez√©rt √°ltal√°ban nem haszn√°lj√°k a hib√°k kezel√©s√©re. Ebben az esetben a f≈ë hiba a `FileNotFoundError`, √©s az a t√©ny, hogy az Errno 2, ahol most vagyunk, nem sz√°m√≠t.

:::tip throw or raise an exception ?!
Egyesek a __throw an exception__ (kiv√©telt dob) kifejez√©st haszn√°lj√°k a __raise an exception__ (kiv√©telt v√°lt ki) helyett. A k√©t kifejez√©s ugyanazt jelenti.
:::

Az utols√≥ r√©sz pontosan megmondja, hogy mi romlott el: __No such file or directory: 'people.csv.'__. M√°s sz√≥val a Python nem tudja elv√©gezni az `open('people.csv')` m≈±veletet, mert nincs `people.csv` nev≈± f√°jl az aktu√°lis mapp√°ban.

Ezt a probl√©m√°t a k√≥d megv√°ltoztat√°s√°val orvosolhatod, de a __.csv__ egy √°ltal√°nos f√°jlkiterjeszt√©s a vessz≈ëvel elv√°lasztott √©rt√©keket tartalmaz√≥ f√°jlok sz√°m√°ra. √ârtelmesebb lenne a __people.cvs__ nevet __people.csv__-re v√°ltoztatni, √≠gy megfelel annak, amit a program keres, √©s a __.csv__ kiterjeszt√©s j√≥l ismert.

## Hib√°k eleg√°ns kezel√©se

A legjobb m√≥dja a __FileNotFoundError__ hiba kezel√©s√©nek, ha a Python √°ltal √°ltal√°ban megjelen√≠tett hiba helyett valami olyat adunk vissza, amit az alkalmaz√°st haszn√°l√≥ szem√©ly val√≥sz√≠n≈±leg jobban meg√©rt. Ehhez egy `try` `except` blokkot √≠rhatsz a k√∂vetkez≈ë alapvet≈ë szintaxissal:

```py
try:     
  # The things you want the code to do
except Exception:     
  # What to do if it can't do what you want it to do
```

√çme, hogyan √≠rhatod √°t a `showfilecontents.py` k√≥dot a hi√°nyz√≥ (_vagy rosszul √≠rt_) f√°jl hib√°j√°nak kezel√©s√©re:

```py
try:
    # Open file and show its name.
    thefile = open("people.csv")
    print(thefile.name)
except Exception:
    print("Sorry, I don't see a file named people.csv here")
```

Mivel el≈ëfordulhat, hogy az a f√°jl, amelyet az alkalmaz√°snak meg kellene nyitnia, hi√°nyzik, a `try:` paranccsal kezdj√ºk, majd megpr√≥b√°ljuk megnyitni az alatta l√©v≈ë f√°jlt. Ha a f√°jl megny√≠lik, akkor a `print()` utas√≠t√°s lefut, √©s megjelen√≠ti a f√°jlnevet. Ha azonban a f√°jl megnyit√°s√°nak k√≠s√©rlete kiv√©telt eredm√©nyez, a program egy √°ltal√°nos hiba√ºzenetet jelen√≠t meg. Ahelyett hogy egy olyan √ºzenetet jelen√≠tene meg, amelyet az √°tlagos sz√°m√≠t√≥g√©p-felhaszn√°l√≥ nem √©rthet.

```txt
Sorry, I don't see a file named people.csv here
```

## Besz√©lj√ºnk pontosabban a kiv√©telekr≈ël

Az el≈ëz≈ë k√≥dp√©ld√°nk eleg√°nsan kezelte a nem tal√°lt f√°jl hib√°t. Egy nagyobb alkalmaz√°sban azonban t√∂bb helyen is el≈ëfordulhat hiba, √©s minden egyes hib√°t m√°sk√©pp kell kezelni. Ehhez t√∂bb kiv√©telt is defini√°lhatunk, ahogyan azt a k√∂vetkez≈ëkben t√°rgyaljuk.

Tegy√ºk fel, hogy manu√°lisan jav√≠tjuk a f√°jlnevet, hogy az eredetileg tervezett __people.csv__ legyen. Mint l√°ttad, amikor futtatod a k√≥dot, √©s nincs hiba, a kimenet csak a f√°jln√©v. A f√°jlnevet ki√≠r√≥ sor alatt egy √∫jabb k√≥dsort adtunk hozz√°:

```py
try:
    # Open file and show its name.
    thefile = open("people.csv")
    print(thefile.name)
    print(thefile.wookems())
except Exception:
    print("Sorry, I don't see a file named people.csv here")
```

Amikor ezt a k√≥dot futtatod, a f√°jln√©v nem jelent probl√©m√°t, √≠gy a kimenet a __people.csv__ f√°jlt jelen√≠ti meg, ahogyan azt v√°rn√°d. A k√∂vetkez≈ë k√≥dsor, a `print(thefile.wookems())` azonban hib√°t dob, mert nem defini√°ltunk `wookems()` nev≈± met√≥dust. Sajnos a hiba√ºzenet tov√°bbra is ugyanaz, mint kor√°bban, pedig a hiba oka az, hogy a Pythonban nincs `.wookems()` nev≈± met√≥dus:

```txt
people.csv
Sorry, I don't see a file named people.csv here
```

Akkor mi√©rt mondja a hiba√ºzenet, hogy a __people.csv__ nev≈± f√°jlt nem tal√°lt√°k meg, amikor tudjuk, hogy megtal√°lta, √©s hogy a k√∂vetkez≈ë k√≥dsor okozza a hib√°t? A probl√©ma az `except Exception:` sorban van, amely azt mondja, hogy "ha ebben a try blokkban b√°rmilyen kiv√©tel keletkezik, akkor a _except_ sor alatti k√≥dot kell v√©grehajtani".

Ahhoz, hogy ezt rendbe tegy√ºk, az `Exception:` helyett a Python √°ltal elkapni k√≠v√°nt konkr√©t kiv√©telt kell megadnunk. De honnan tudjuk, hogy mi az a konkr√©t kiv√©tel? Egyszer≈±. A kiv√©tel, amelyet kiv√©telkezel√©s n√©lk√ºl dobott:

```txt
FileNotFoundError: [Errno 2] No such file or directory: 'people.csv'
```

Az els≈ë sz√≥ a kiv√©tel neve, amelyet az √°ltal√°nos Exception helyett haszn√°lhatunk, p√©ld√°ul √≠gy:

```py
try:
    # Open file and show its name.
    thefile = open("people.csv")
    print(thefile.name)
    print(thefile.wookems())
except FileNotFoundError:
    print("Sorry, I don't see a file named people.csv here")
```

Igaz, a FileNotFoundError elk√ºl√∂n√≠t√©se nem seg√≠t a nem l√©tez≈ë met√≥dus megh√≠v√°s√°val kapcsolatban. A rossz met√≥dusn√©v azonban nem kiv√©tel. Ez egy programoz√°si hiba, amelyet ki kell jav√≠tani a k√≥dban a `.wookems()` helyettes√≠t√©s√©vel a haszn√°lni k√≠v√°nt met√≥dusn√©vvel.

Legal√°bb a megjelen≈ë hiba√ºzenet nem a f√©lrevezet≈ë _Sorry, I don't see a file named people.csv here_. A k√≥d norm√°lisan m≈±k√∂dik, ez√©rt utas√≠t√°sra megjelen√≠ti a f√°jlnevet. Azt√°n amikor el√©ri a rossz `.wookem()` met√≥dust tartalmaz√≥ sort, hib√°t dob - de nem a f√°jln√©v nem tal√°l√°s√°val kapcsolatos hib√°t. Megjelen√≠ti a helyes hiba√ºzenetet erre a hib√°ra, az objektumnak nincs __'wookems'__ attrib√∫tuma.

```py
Traceback (most recent call last):
  File "/Python/1.py", line 5, in <module>
    print(thefile.wookems())
          ^^^^^^^^^^^^^^^
AttributeError: '_io.TextIOWrapper' object has no attribute 'wookems'
```

Ism√©tlem, ha a `.wookems` hiba kezel√©s√©re gondolsz, ez nem olyan kiv√©tel, amelyre __exception__ √≠rsz. Kiv√©telek akkor fordulnak el≈ë, ha valami a programon k√≠v√ºl, amit≈ël a program f√ºgg, nem el√©rhet≈ë. A programoz√°si hib√°k, mint p√©ld√°ul a nem l√©tez≈ë met√≥dusnevek, a programon bel√ºli hib√°k, amelyeket a k√≥dot √≠r√≥ programoz√≥nak kell kijav√≠tania.

## Az alkalmaz√°s √∂sszeoml√°s√°nak megakad√°lyoz√°sa

Egy try blokkban egym√°sra halmozhatod a except: utas√≠t√°sokat a k√ºl√∂nb√∂z≈ë hib√°k kezel√©s√©re. Csak arra figyelj√ºnk, hogy amikor a kiv√©tel bek√∂vetkezik, a program mindegyiket a tetej√©t≈ël kezdve vizsg√°lja meg. Ha tal√°l olyat, amely megfelel a kiv√©telnek, akkor azt h√≠vja el≈ë. Ha olyan kiv√©tel l√©pett fel, amely nem kezelt, akkor a Python standard hiba√ºzenet√©t kapjuk meg. De ezt is meg lehet ker√ºlni.

Ha el akarjuk ker√ºlni az √∂sszes Python hiba√ºzenetet, akkor a k√≥d utols√≥ kiv√©tel√©t az `except Exception:` haszn√°ljuk. Ez a sor azt jelenti: "Ha a bek√∂vetkezett hib√°t m√©g nem kezelte valamelyik el≈ëz≈ë kiv√©tel, haszn√°ld helyette az Exception". M√°s sz√≥val, a __catch-all exception__ minden olyan kiv√©telt kezel, amelyet a k√≥dban m√©g nem kezeltek. Itt p√©ld√°ul k√©t kezel≈ë van, egy a __file not found__ hib√°ra √©s egy minden m√°sra.

```py
try:
    # Open file and show its name.
    thefile = open("people.csv")
    # Print a couple blank lines then the first line from the file.
    print("\n\n", thefile.readline())
    # Close the file.
    thefile.closed()
except FileNotFoundError:
    print("Sorry, I don't see a file named people.csv here")
except Exception:
    print("Sorry, something else went wrong")
```

:::warning Tudjuk, hogy nem
tanultunk az `open`-r≈ël, a `readline`-r√≥l √©s a `close`-r√≥l, de emiatt ne agg√≥djunk most. Jelen pillanatban csak a kiv√©telkezel√©ssel foglalkozunk, ami a k√≥d `try:` √©s `except:` r√©szei.
:::

A k√≥d futtat√°sa a k√∂vetkez≈ë kimenetet eredm√©nyezi:

```txt
Username,FirstName,LastName,Role,DateJoined
Sorry, something else went wrong
```

Az els≈ë sor a _people.csv_ f√°jl els≈ë sor√°t jelen√≠ti meg. A m√°sodik sor a m√°sodik except: utas√≠t√°s kimenete, amely √≠gy sz√≥l: __Sorry, something else went wrong__. Ez az √ºzenet hom√°lyos, √©s nem seg√≠t a probl√©ma megtal√°l√°s√°ban.

Ahelyett, hogy csak egy √°ltal√°nos √ºzenetet √≠rna ki egy ismeretlen kiv√©telre, a hiba√ºzenetet egy v√°ltoz√≥ban r√∂gz√≠theti, majd a v√°ltoz√≥ tartalm√°t megjelen√≠tve l√°thatja az √ºzenetet. Mint √°ltal√°ban, a v√°ltoz√≥t b√°rhogyan nevezheted, b√°r sokan haszn√°lj√°k az `e` vagy `err` nevet a hiba r√∂vid√≠t√©sek√©nt.

Vegy√ºk p√©ld√°ul az el≈ëz≈ë k√≥d √°talak√≠t√°s√°nak k√∂vetkez≈ë v√°ltozat√°t. Az Exception, most egy `e`-t tartalmaz, ami azt jelenti, hogy "a hiba√ºzenetet egy `e` nev≈± v√°ltoz√≥ba tedd". Ezut√°n a k√∂vetkez≈ë sor a `print(e)` seg√≠ts√©g√©vel jelen√≠ti meg az `e` v√°ltoz√≥ tartalm√°t:

```py
try:
    # Open file and show its name.
    thefile = open("people.csv")
    # Print a couple blank lines then the first line from the file.
    print("\n\n", thefile.readline())
    thefile.wigwam()
except FileNotFoundError:
    print("Sorry, I don't see a file named people.csv here")
except Exception as e:
    print(e)
```

A k√≥d futtat√°sa a k√∂vetkez≈ëket jelen√≠ti meg:


```txt
Username,FirstName,LastName,Role,DateJoined
'_io.TextIOWrapper' object has no attribute 'wigwam'
```

Az els≈ë sor csak a __people.csv__ f√°jl els≈ë sora.
Nincs hiba a k√≥dban, √©s az a f√°jl is megvan, teh√°t minden rendben ment. 

A m√°sodik sor:

```txt
'_io.TextIOWrapper' object has no attribute 'wigwam'
```

Ez nem egyszer≈±, de jobb, mint a "Something else went wrong". Legal√°bb az a r√©sz, hogy az objektumnak nincs `'wigwam'` attrib√∫tuma, tudatja vel√ºnk, hogy a probl√©m√°nak k√∂ze van a `wigwam` sz√≥hoz. A hib√°t eleg√°nsan kezelted, √©s az alkalmaz√°s nem omlott √∂ssze. Illetve kaptunk n√©mi inform√°ci√≥t a hib√°r√≥l, ami hasznos lehet sz√°modra, m√©g akkor is, ha nem biztos, hogy hasznos azoknak, akik az alkalmaz√°st √∫gy haszn√°lj√°k, hogy nem ismerik annak bels≈ë m≈±k√∂d√©s√©t.

## Egy `else` hozz√°ad√°sa a mixhez

Az legut√≥bbi p√©ld√°nkban egy kiv√©telt haszn√°ltunk a nem tal√°lt f√°jl hib√°inak kezel√©s√©re, √©s egy m√°sodik kiv√©telt minden m√°sra. A val√≥ √©letben azonban el≈ëfordulhat, hogy sokkal t√∂bb hib√°t kell kezeln√ºnk. √âs ha nincs hiba, akkor azt szeretn√©nk, hogy a v√©grehajt√°s norm√°lisan folytat√≥djon. Az `else`-t az utols√≥ felt√©telhez haszn√°lhatod a k√∂vetkez≈ëk√©ppen:

```py
try:     
The thing that might cause an exceptioncatch a common exception:
Explain the problem 
catch Exception as e:
Show the generic error message
else:
Continue on here only if no exceptions raised
```

Ha ezt a k√≥dot egyszer≈±en leford√≠tjuk, a folyamat logik√°ja a k√∂vetkez≈ë: 

Megpr√≥b√°ljuk megnyitni a f√°jlt.
Ha a f√°jl nincs ott, sz√≥ljon, √©s √°lljon le.
Ha valami m√°s hiba van, mutassa az √°ltal√°nos hiba√ºzenetet, √©s √°ll√≠tsa le.
Ellenkez≈ë esetben
Folytassa a k√≥d t√∂bbi r√©sz√©t.

Ha a `try:`-t arra a dologra korl√°tozzuk, ami a legnagyobb val√≥sz√≠n≈±s√©ggel kiv√©telt fog kiv√°ltani, akkor meg√°ll√≠thatjuk a k√≥dot, miel≈ëtt tov√°bb pr√≥b√°lkozna. Ha azonban nem t√∂rt√©nik kiv√©tel, a k√≥d norm√°lisan folytat√≥dik tov√°bb, az `else` alatt, ahol a kor√°bbi kiv√©telek m√°r nem sz√°m√≠tanak. Itt van az √∂sszes k√≥d, komment√°rokkal, amelyek elmagyar√°zz√°k, mi t√∂rt√©nik:

```py
try:
    # Open the file named people.csv
    thefile = open("people.csv")
# Watch for common error and stop program if it happens.
except FileNotFoundError:
    print("Sorry, I don't see a file named people.csv here")
# Catch any unexpected error and stop the program if one happens.
except Exception as err:
    print(err)
# Otherwise, if nothing bad has happened by now, just keep going.
else:
    # File must be open by now if we got here.
    print("\n")  # Print a blank line.
    # Print each line from the file.
    for one_line in thefile:
        print(one_line)
    thefile.close()
    print("Success!")
```


:::danger ‚ùó
Mint mindig a Pythonban, a beh√∫z√°sok sokat sz√°m√≠tanak. Gy≈ëz≈ëdj meg r√≥la, hogy a k√≥dodat a fejezetben bemutatott m√≥don beh√∫zod. Ellenkez≈ë esetben a k√≥dod nem fog megfelel≈ëen m≈±k√∂dni.
:::


## A try ... except ... else ... finally haszn√°lata

Ha megn√©zz√ºk a Python kiv√©telkezel√©s teljes szintaxis√°t, a v√©g√©n m√©g egy opci√≥t tal√°lunk, p√©ld√°ul ezt:

```py
try:    
try to do this
except:
if x happens, stop here
except Exception as e:    
if something else bad happens, stop here
else:    
if no exceptions, continue on normally here
finally:    
do this code no matter what happened above
```

A `finally` k√≥d akkor ker√ºl v√©grehajt√°sra, amikor a `try` blokk v√©get √©r, f√ºggetlen√ºl att√≥l, hogy mi t√∂rt√©nik. Ha p√©ld√°ul egy f√ºggv√©nyen bel√ºl vagy, √©s egy `except` blokk a `return`-t haszn√°lja a f√ºggv√©nyb≈ël val√≥ kil√©p√©shez, a `finally` k√≥d akkor is v√©grehajt√≥dik. Ilyen funkci√≥ n√©lk√ºl a `finally` blokk egyen√©rt√©k≈± lenne azzal, hogy a k√≥dj√°t a `try` blokk ut√°n √©s azon k√≠v√ºl helyezz√ºk el.

Ennek illusztr√°l√°s√°ra itt van n√©h√°ny k√≥d, amely elv√°rja, hogy a __people.csv__ nev≈± k√ºls≈ë er≈ëforr√°s el√©rhet≈ë legyen a k√≥d sz√°m√°ra:

```py
print("Do this first")
try:
    open("people.csv")
except FileNotFoundError:
    print("Cannot find file named people.csv")
except Exception as e:
    print(e)
else:
    print("Show this if there is no exception.")
finally:
    print("This is in the finally block")
    print("This is outside the try...except...else...finally")
```

Ha ezt a k√≥dot futtatjuk a mapp√°ban l√©v≈ë __people.csv__ nev≈± f√°jllal, ezt a kimenetet kapja:

```txt
Do this first
Show this if no exception.
This is in the finally block
This is outside the try...except...else...finally
```

Egyik kiv√©teltjelent≈ë k√≥d sem hajt√≥dott v√©gre, mivel az `open()` utas√≠t√°s k√©pes volt megnyitni a __people.csv__ nev≈± f√°jlt.
Ha ezt a k√≥dot √∫gy futtatja, hogy nincs __people.csv__ nev≈± f√°jl ugyanabban a mapp√°ban, a k√∂vetkez≈ë eredm√©nyt kapja:

```txt
Do this first
Cannot find file named people.csv
This is in the finally block
This is outside the try...except...else...finally
```

Ez√∫ttal a k√≥d nem tal√°lja a __people.csv__ nev≈± f√°jlt. De az alkalmaz√°s nem zuhan √∂ssze. Ink√°bb folytatja a k√≥d t√∂bbi r√©sz√©nek v√©grehajt√°s√°t.

Ezek a p√©ld√°k j√≥l szeml√©ltetik, hogy pontosan hogyan szab√°lyozhatjuk, mi t√∂rt√©njen a felhaszn√°l√≥i hib√°kra vagy m√°s k√ºls≈ë kiv√©telekre √©rz√©keny program egy kis r√©sz√©ben, mik√∂zben a t√∂bbi k√≥dot norm√°lisan futtathatjuk.

## Saj√°t kiv√©telek k√©sz√≠t√©se

A Python rengeteg be√©p√≠tett kiv√©tellel rendelkezik a hib√°k felismer√©s√©re √©s azonos√≠t√°s√°ra, amint azt a k√≥d √≠r√°sa √©s tesztel√©se sor√°n l√°tni fogod, k√ºl√∂n√∂sen az els≈ë tanul√°skor. Azonban nem korl√°toz√≥dsz a be√©p√≠tett kiv√©telekre. Ha az alkalmaz√°sodban olyan sebezhet≈ës√©g van, amelyre a be√©p√≠tett kiv√©telek nem terjednek ki, akkor k√©sz√≠thetsz egy saj√°tot.

A saj√°t hiba k√©sz√≠t√©se √°ltal√°nos szintaxisa a k√∂vetkez≈ë:

```py
raise error
```

Az `error`-t helyettes√≠ts√ºk annak az ismert hib√°nak a nev√©vel, amelyet ki akarunk v√°ltani (p√©ld√°ul `FileNotFoundError`). Vagy, ha a hiba nem tartozik a be√©p√≠tett hib√°k k√∂z√©, akkor egyszer≈±en haszn√°lhatja a `raise Exception`-t, √©s ez v√©grehajtja azt, ami a `catch Exception:` alatt van a k√≥dban.

Mondjuk, hogy k√©t felt√©telnek kell teljes√ºlnie ahhoz, hogy a program sikeresen fusson: 

- A people.csv f√°jlnak l√©teznie kell, hogy meg tudja nyitni.
- A people.csv f√°jlnak egyn√©l t√∂bb adatsort kell tartalmaznia. Az els≈ë sor oszlopneveket tartalmaz, nem adatokat, √≠gy ha a f√°jl csak oszlopc√≠meket tartalmaz, akkor √ºresnek tekintj√ºk.

√çme egy p√©lda arra, hogyan kezelhetj√ºk a helyzet kiv√©telkezel≈ë r√©sz√©t:

```py
try:
    # Open the file
    thefile = open("people.csv")
    # Count the number of lines in file.
    line_count = len(thefile.readlines())
    # If there are fewer than 2 lines, raise exception.
    if line_count < 2:
        raise Exception
    # Handles missing file error.
except FileNotFoundError:
    print("\nThere is no people.csv file here")
# Handles all other exceptions
except Exception as e:
    # Show the error.
    print("\n\nFailed: The error was " + str(e))
    # Close the file.
    thefile.close()
```

N√©zz√ºk v√©gig a k√≥dot. Az els≈ë sorok a __people.csv__ f√°jlt pr√≥b√°lj√°k megnyitni:

```py
try:
    # Open the file
    thefile = open("people.csv")
```

Tudjuk, hogy ha a __people.csv__ f√°jl nem l√©tezik, a v√©grehajt√°s a k√∂vetkez≈ë kiv√©telhez ugrik, amely k√∂zli a felhaszn√°l√≥val, hogy a f√°jl nem l√©tezik:

```py
except FileNotFoundError:
    print("\nThere is no people.csv file here")
```

Felt√©telezve, hogy a f√°jl meg lett tal√°lva, √©s nem t√∂rt√©nt hiba, √©s a f√°jl most nyitva van, a k√∂vetkez≈ë sor megsz√°molja, hogy h√°ny sor van a f√°jlban:

```py
line_count = len(thefile.readlines())
```

Ha a f√°jl √ºres, a soroksz√°ma 0. Ha a f√°jl csak oszlopc√≠meket tartalmaz, p√©ld√°ul √≠gy:

```txt
Username,FirstName,LastName,DateJoined
```

a hossz 1 lesz. Azt akarjuk, hogy a k√≥d t√∂bbi r√©sze csak akkor fusson, ha a f√°jl hossza 2 vagy t√∂bb. Teh√°t ha a sorsz√°m 2-n√©l kevesebb, a k√≥d kiv√©telt fog gener√°lni. Lehet, hogy nem tudod, hogy mi ez a kiv√©tel, ez√©rt a `raise Exception` (nagy E-vel) seg√≠ts√©g√©vel k√∂zl√∂d az alkalmaz√°snak, hogy egy √°ltal√°nos kiv√©telt dobjon:

```py
if line_count < 2:
        raise Exception
```

Az √°ltal√°nos kiv√©telek √≠gy n√©znek ki:

```py
except Exception as e:
    # Show the error.
    print("\n\nFailed: The error was " + str(e))
    # Close the file.
    thefile.close()
```

Az `e` v√°ltoz√≥ megragadja a kiv√©telt, √©s a k√∂vetkez≈ë `print` utas√≠t√°s megjelen√≠ti a kiv√©telt. Tegy√ºk fel, hogy lefuttatjuk ezt a k√≥dot, √©s a __people.csv__ √ºres vagy hi√°nyos. A kimenet a k√∂vetkez≈ë lenne:

```txt
Failed: The error was
```

Megjegyezz√ºk, hogy nincs magyar√°zat a hib√°ra, mert mi a

```py
except Exception as e:
```

haszn√°ljuk.

Ne feledj√ºk, hogy az `Exception` b√°rmilyen hib√°ra vonatkozik, nem pedig olyan hib√°ra, amelynek konkr√©t neve az `e` nev≈± v√°ltoz√≥ban van t√°rolva. Ha olyan hib√°t szeretn√©nk dobni, amelyhez hiba√ºzenet is tartozik, helyettes√≠ts√ºk az `Exceptiont` egy konkr√©t Python kiv√©tel nev√©vel. Az al√°bbi k√≥dban p√©ld√°ul az √°ltal√°nos `Exceptiont` a specifikusabb `FileNotFoundError`-ra cser√©lt√ºk:

```py
if line_count < 2:    
  raise FileNotFoundError
```

De ha ezt √≠gy csin√°ljuk, akkor a `FileNotFoundError` megh√≠v√°sra ker√ºl, √©s megjelen√≠ti a __There is no people.csv file__, ami ebben az esetben nem igaz, √©s nem ez a probl√©ma oka. Van __people.csv__ f√°jl, csak nincs rajta adat, amin v√©gighaladhatn√°nk. Amire sz√ºks√©ged van, az egy egy√©ni kiv√©telkezel≈ë erre a kiv√©telre.

Pythonban minden kiv√©tel objektum, olyan oszt√°lyok p√©ld√°nyai, amelyek a Pythonban az `Errors` alaposzt√°lyb√≥l √∂r√∂kl≈ëdnek. A saj√°t kiv√©tel l√©trehoz√°s√°hoz el≈ësz√∂r is import√°lni kell az `Exception` oszt√°lyt, hogy alaposzt√°lyk√©nt haszn√°lhassuk (_hasonl√≥an ahhoz, ahogy a `Member` oszt√°ly is alaposzt√°ly volt a k√ºl√∂nb√∂z≈ë t√≠pus√∫ felhaszn√°l√≥k sz√°m√°ra_). Ezut√°n defini√°ljuk a hib√°nkat ennek az alaposzt√°lynak az aloszt√°lyak√©nt. Ez a k√≥d a f√°jl elej√©re ker√ºl, √≠gy azel≈ëtt v√©grehajt√≥dik, miel≈ëtt b√°rmely m√°s k√≥d megpr√≥b√°ln√° haszn√°lni az egy√©ni kiv√©telt:

```py
# Define Python user-defined exceptions
class Error(Exception):    
  """Base class for other exceptions"""
      pass 

# Your custom error (inherits from Error)
class EmptyFileError(Error):
      pass
```

Mint kor√°bban m√°r volt r√≥la sz√≥, hogy a `pass` minden oszt√°lyban azt mondja a Pythonnak, hogy __"Tudom, hogy ebben az oszt√°lyban nincs k√≥d, √©s ez itt rendben van. Nem kell kiv√©telt gener√°lnod, hogy ezt k√∂z√∂ld velem"__.
Most, hogy l√©tezik egy `EmptyFileError` nev≈± kiv√©teloszt√°ly, ezt a kiv√©telt akkor is ki lehet v√°ltani, ha a f√°jlnak nincs elegend≈ë tartalma:

```py
# If there are fewer than 2 lines, raise exception.
if line_count < 2:
  raise EmptyFileError
# Handles my custom error for too few rows.
except EmptyFileError:    
  print("\nYour people.csv file doesn't have enough stuff.")
```

A k√∂vetkez≈ëk√©pp alakulnak a dolgok, amikor a k√≥d fut. Ha egy√°ltal√°n nincs __people.csv__ f√°jl, akkor ez a hiba jelenik meg:

```txt
There is no people.csv file here.
```

Ha van __people.csv__ f√°jl, de az √ºres vagy csak oszlopc√≠meket tartalmaz, a program a k√∂vetkez≈ëket jelen√≠ti meg:

```txt
Your people.csv file doesn't have enough stuff.
```

Felt√©telezve, hogy egyik hiba sem t√∂rt√©nt meg, az `else:` alatti k√≥d lefut, √©s megjelen√≠ti a f√°jlban l√©v≈ë adatokat.

Amint l√°thatod, a kiv√©telkezel√©ssel teh√°t megtervezheted a k√≥dodban l√©v≈ë sebezhet≈ës√©gek √°ltal okozott hib√°kat. Nem a k√≥dodban l√©v≈ë hib√°kra vagy k√≥dol√°si hib√°kra gondolunk, hanem olyan k√ºls≈ë er≈ëforr√°sokra, amelyekre a programnak sz√ºks√©ge van a helyes fut√°shoz.

A teljes k√≥d:

```py
# Define Python user-defined exceptions
class Error(Exception):
    """Base class for other exceptions"""
    pass


# Your custom error (inherits from Error)
class EmptyFileError(Error):
    pass

try:
    # Open the file
    thefile = open("people.csv", "r")
    # Count the number of lines in file.
    lines = thefile.readlines()
    line_count = len(lines)
    # If there are fewer than 2 lines, raise exception.
    if line_count < 2:
        raise EmptyFileError
# Handles missing file error.
except FileNotFoundError:
    print("\nThere is no people.csv file here")
except EmptyFileError:
    print("\nYour people.csv file doesn't have enough stuff.")
except Exception as e:
    # Show the error.
    print("\n\nFailed: The error was " + str(e))
    # Close the file.
    thefile.close()
else:
    # File must be open by now if we got here.
    print("\n")  # Print a blank line.

    # Print each line from the file.
    for one_line in lines:
        print(one_line)
    thefile.close()
    print("Success!")
```

Ha a k√ºls≈ë er≈ëforr√°sok hi√°nyoznak vagy nem elegend≈ëek, nem kell hagynod, hogy a program egyszer≈±en √∂sszeomoljon, √©s egy hiba√ºzenetet jelen√≠tsen meg, amely zavarba hozza a felhaszn√°l√≥idat. Ehelyett elkaphatjuk a kiv√©telt, √©s megjelen√≠thet√ºnk a felhaszn√°l√≥knak egy sz√∂veget, amely pontosan megmondja neki, hogy mi a baj, ami seg√≠thet a probl√©ma kijav√≠t√°s√°ban, √©s a program √∫jb√≥li, ez√∫ttal sikeres futtat√°s√°ban. Err≈ël sz√≥l a kiv√©telkezel√©s.